Workbook

Sheet Sessions
A1: MTC session catalog
A2: 134 session records . Filter by focus area, tags, or review status . Repeated offerings are grouped
A4: Session ID | B4: Session title | C4: Short description | D4: Primary focus | E4: Additional focus areas | F4: Topic tags | G4: Documented date(s) | H4: Program(s) | I4: Offerings | J4: Review needed | K4: Source URL | L4: Session folder URL (latest offering)
A5: MTC-001 | B5: 3-Act Math Tasks | C5: Experience a three-act task about draining a pool and examine how a visual question, needed information, and a reveal support mathematical modeling. | D5: Teaching & Learning | E5: Mathematical Modeling | F5: 3-Act tasks; Desmos; questioning; modeling | G5: 2021-06-17 | H5: Summer Institute | I5: =COUNTIF(Offerings!$B$5:$B$145,A5) -> 1 | J5: =IF(COUNTIFS(Offerings!$B$5:$B$145,A5,Offerings!$K$5:$K$145,"Yes")>0,"Yes","No") -> No | K5: https://docs.google.com/presentation/d/1n_7f4sxYuztvXVN8gZ-NnK-xv4gQRV5r_x4P9LyLR2A/edit?usp=drivesdk | L5: https://drive.google.com/drive/folders/1e2q-g-xXdeIYu1vMIBuR4E2F1yCZiMxQ
A6: MTC-002 | B6: 4-Game Night | C6: Compare strategies and possible generalizations across four games: The Child and the Witch, Nim, The Fox and the Rabbit, and The Rook Game. | D6: Game Theory | E6: Logic & Proof | F6: Nim; rook game; fox and rabbit; child and witch | G6: 2024-02-06 | H6: MTC academic-year session | I6: =COUNTIF(Offerings!$B$5:$B$145,A6) -> 1 | J6: =IF(COUNTIFS(Offerings!$B$5:$B$145,A6,Offerings!$K$5:$K$145,"Yes")>0,"Yes","No") -> No | K6: https://drive.google.com/file/d/1zL70vEoZ6Aae0qdb6JW5lnACC4mTBQaa/view?usp=drivesdk | L6: https://drive.google.com/drive/folders/1gUdo__wtMXb0xibi5HdtlAkjX3OzRTI1
A7: MTC-003 | B7: Addressing Unfinished Learning | C7: Explore ways to address unfinished learning with an equity mindset and collaborate on instructional plans. | D7: Teaching & Learning | F7: equity; unfinished learning; instructional planning | G7: 2022-01-22 | H7: PLUS Math | I7: =COUNTIF(Offerings!$B$5:$B$145,A7) -> 1 | J7: =IF(COUNTIFS(Offerings!$B$5:$B$145,A7,Offerings!$K$5:$K$145,"Yes")>0,"Yes","No") -> No | K7: https://drive.google.com/file/d/1bASee8-xo4xHQZQi3HM7F3FOFzsfH4TX/view?usp=drivesdk | L7: https://drive.google.com/drive/folders/1iaJ8EXGtfXLv8gjdcBmZKyAShomA-9JP
A8: MTC-004 | B8: Alternate Algorithms | C8: Compare alternative addition and multiplication methods, including lattice algorithms, partial products, and stick multiplication. | D8: Number Sense & Arithmetic | E8: Teaching & Learning | F8: lattice arithmetic; partial products; multiple methods | G8: 2018-06-18 to 2018-06-21 (institute window) | H8: Summer Institute | I8: =COUNTIF(Offerings!$B$5:$B$145,A8) -> 1 | J8: =IF(COUNTIFS(Offerings!$B$5:$B$145,A8,Offerings!$K$5:$K$145,"Yes")>0,"Yes","No") -> Yes | K8: https://docs.google.com/presentation/d/1u6vBmLM7voR7AKzROirAZsQji_7M82HC/edit?usp=drivesdk&ouid=109901495158487957834&rtpof=true&sd=true | L8: https://drive.google.com/drive/folders/1SdYWc2admzVtcf9FW5D6I12sTV-2Ivi4
A9: MTC-006 | B9: Assess, Activate, and Build on Prior Knowledge | C9: Use math-vocabulary activities and structured reading discussion to consider how instruction can assess, activate, and build on students’ prior knowledge. | D9: Teaching & Learning | F9: ICUCARE; prior knowledge; math vocabulary; Catch Phrase | G9: 2025-06-13 | H9: Summer Institute | I9: =COUNTIF(Offerings!$B$5:$B$145,A9) -> 1 | J9: =IF(COUNTIFS(Offerings!$B$5:$B$145,A9,Offerings!$K$5:$K$145,"Yes")>0,"Yes","No") -> No | K9: https://docs.google.com/presentation/d/1ScAfRKcWWTDrnk6C2kW1XyS0nk0lEoGq/edit?usp=drivesdk&ouid=109901495158487957834&rtpof=true&sd=true | L9: https://drive.google.com/drive/folders/1jiWrWvgndwUoN-3kKi7cHTNb1bV9KyRS
A10: MTC-007 | B10: Assessing Mathematical Modeling | C10: Discuss assessment of mathematical modeling using the assigned GAIMME reading and a collaborative response activity. | D10: Teaching & Learning | E10: Mathematical Modeling | F10: assessment; GAIMME; modeling | G10: 2021-06-18 | H10: Summer Institute | I10: =COUNTIF(Offerings!$B$5:$B$145,A10) -> 1 | J10: =IF(COUNTIFS(Offerings!$B$5:$B$145,A10,Offerings!$K$5:$K$145,"Yes")>0,"Yes","No") -> No | K10: https://docs.google.com/document/d/1XgBPtwa7dVUiBdYAa1nvv7DqLhWe7ho8BS23HndmozU/edit?usp=drivesdk | L10: https://drive.google.com/drive/folders/1jMaUXv_moFqp4vPk7rMqgcL-NFSsSY0E
A11: MTC-008 | B11: Big Numbers | C11: Build and compare very large numbers using exponentiation and factorials, and examine ways to represent quantities too large to write digit by digit. | D11: Number Sense & Arithmetic | E11: Algebra | F11: exponents; factorials; growth rates; large numbers | G11: 2026-03-03 | H11: MTC academic-year session | I11: =COUNTIF(Offerings!$B$5:$B$145,A11) -> 1 | J11: =IF(COUNTIFS(Offerings!$B$5:$B$145,A11,Offerings!$K$5:$K$145,"Yes")>0,"Yes","No") -> No | K11: https://drive.google.com/file/d/14zGzB4zObSrzZB6b3P96l2fWO2xcnhwA/view?usp=drivesdk | L11: https://drive.google.com/drive/folders/1Lh8pWV2kc1VTG6jOyfqx_ZarEunyXWkU
A12: MTC-009 | B12: Blind Stork: Collecting and Modeling Data | C12: Collect balance-test data, choose appropriate visualizations, and use Desmos to explore statistical summaries and relationships. | D12: Probability & Statistics | E12: Mathematical Modeling | F12: Desmos; data collection; graph selection; regression | G12: 2023-06-20 | H12: Summer Institute | I12: =COUNTIF(Offerings!$B$5:$B$145,A12) -> 1 | J12: =IF(COUNTIFS(Offerings!$B$5:$B$145,A12,Offerings!$K$5:$K$145,"Yes")>0,"Yes","No") -> No | K12: https://docs.google.com/presentation/d/1eBBhuPUH1Sk8yqbKnEZNtrYFpvk6s9e8/edit?usp=drivesdk&ouid=109901495158487957834&rtpof=true&sd=true | L12: https://drive.google.com/drive/folders/1NVpERNtguPK1wdF3QHYUFpueMv7iabZH
A13: MTC-010 | B13: Blokus and Polyominoes | C13: Play Blokus and investigate the geometry and tiling properties of polyominoes. | D13: Geometry | E13: Combinatorics | F13: polyominoes; tiling; Blokus | G13: 2018-11-06 | H13: MTC academic-year session | I13: =COUNTIF(Offerings!$B$5:$B$145,A13) -> 1 | J13: =IF(COUNTIFS(Offerings!$B$5:$B$145,A13,Offerings!$K$5:$K$145,"Yes")>0,"Yes","No") -> No | K13: https://drive.google.com/file/d/11LMWsczRyxmNkLaP_2Zb_5QISDRARhAM/view?usp=drivesdk | L13: https://drive.google.com/drive/folders/1i6fFH73dedn7uE3D5CrxC0mC5dTf-zL8
A14: MTC-011 | B14: Bringing Data into Classrooms | C14: Investigate participant car-survey data using one-variable and multivariable questions, then discuss how to bring data investigations into classrooms. | D14: Probability & Statistics | E14: Teaching & Learning | F14: GAISE II; survey data; Google Sheets; statistical questions | G14: 2023-06-22 | H14: Summer Institute | I14: =COUNTIF(Offerings!$B$5:$B$145,A14) -> 1 | J14: =IF(COUNTIFS(Offerings!$B$5:$B$145,A14,Offerings!$K$5:$K$145,"Yes")>0,"Yes","No") -> No | K14: https://docs.google.com/presentation/d/1K2tmaLErEVOhhciOyIDLkyqm0f5y_t4qHGoiHP-xoK8/edit?usp=drivesdk | L14: https://drive.google.com/drive/folders/1fbqt59z4P4_XYyOWhZAfhpE3u8oeSetz
A15: MTC-012 | B15: Bubbling Cauldrons | C15: Place successive integers into cauldrons so that no two numbers in a cauldron add to a third number there, then vary the number of cauldrons and starting value. | D15: Combinatorics | E15: Number Theory | F15: sum-free sets; constraints; generalization | G15: 2022-03-01 | H15: MTC academic-year session | I15: =COUNTIF(Offerings!$B$5:$B$145,A15) -> 1 | J15: =IF(COUNTIFS(Offerings!$B$5:$B$145,A15,Offerings!$K$5:$K$145,"Yes")>0,"Yes","No") -> No | K15: https://drive.google.com/file/d/14bi8fihcIm4Args2WhVR4CV7iAsAnimL/view?usp=drivesdk | L15: https://drive.google.com/drive/folders/1S5El3eNXpjIllIZfOLvcKPqZt-7IHb44
A16: MTC-013 | B16: Bulgarian Solitaire | C16: Rearrange piles of counters according to Bulgarian Solitaire rules and investigate stable configurations, cycles, and ways to classify arrangements. | D16: Algebra | E16: Combinatorics | F16: dynamical systems; partitions; cycles | G16: 2019-09-03 | H16: MTC academic-year session | I16: =COUNTIF(Offerings!$B$5:$B$145,A16) -> 1 | J16: =IF(COUNTIFS(Offerings!$B$5:$B$145,A16,Offerings!$K$5:$K$145,"Yes")>0,"Yes","No") -> No | K16: https://drive.google.com/file/d/1gfAyb62Hqiwmjzht8VDSoYEYMegTx87L/view?usp=drivesdk | L16: https://drive.google.com/drive/folders/11SA0qc1_8-DXGqh_XV_yRZnR-bkzOPXu
A17: MTC-014 | B17: Candy Sharing | C17: Play a repeated candy-sharing game and investigate when the process stabilizes, repeats, or continues indefinitely. | D17: Algebra | E17: Algorithms & Computing | F17: dynamical systems; iteration; cycles | G17: 2017-11-07 | H17: MTC academic-year session | I17: =COUNTIF(Offerings!$B$5:$B$145,A17) -> 1 | J17: =IF(COUNTIFS(Offerings!$B$5:$B$145,A17,Offerings!$K$5:$K$145,"Yes")>0,"Yes","No") -> No | K17: https://drive.google.com/file/d/0B4cCTfJeL7_dNG1SRGJIUWh4R2c/view?usp=drivesdk&resourcekey=0-jEyNsfAltNj9lA6QZChKPQ | L17: https://drive.google.com/drive/folders/0B4cCTfJeL7_demd3d3RFTkZKWnM?resourcekey=0-MzT-jVW9rtLCFP_7rXBvcw
A18: MTC-016 | B18: Connecting Math, Community, and Equity Through Tax Rates | C18: Investigate tax brackets and rates through a relevant modeling task, then connect the activity with peer expertise and knowledge of students. | D18: Algebra | E18: Mathematical Modeling; Teaching & Learning | F18: tax rates; financial literacy; ICUCARE; equity | G18: 2025-06-17 | H18: Summer Institute | I18: =COUNTIF(Offerings!$B$5:$B$145,A18) -> 1 | J18: =IF(COUNTIFS(Offerings!$B$5:$B$145,A18,Offerings!$K$5:$K$145,"Yes")>0,"Yes","No") -> No | K18: https://docs.google.com/presentation/d/14r7xF06YREoURZK8WDV20sgtxwqRhS9q/edit?usp=drivesdk&ouid=109901495158487957834&rtpof=true&sd=true | L18: https://drive.google.com/drive/folders/11vxjmRb0TS8JFvDvhD_iZ-EzytMid970
A19: MTC-017 | B19: Create Your Own Graph Talk | C19: Select or create a graph, anticipate questions, and plan how to facilitate a graph talk with students. | D19: Teaching & Learning | E19: Probability & Statistics | F19: graph talks; CODAP; task design | G19: 2023-06-21 | H19: Summer Institute | I19: =COUNTIF(Offerings!$B$5:$B$145,A19) -> 1 | J19: =IF(COUNTIFS(Offerings!$B$5:$B$145,A19,Offerings!$K$5:$K$145,"Yes")>0,"Yes","No") -> No | K19: https://docs.google.com/presentation/d/1LWIWmJ3EBrNjSHOYKbrKgh5hV4SagZqu/edit?usp=drivesdk&ouid=109901495158487957834&rtpof=true&sd=true | L19: https://drive.google.com/drive/folders/1PT_C7BaoICdlpDmqhk9gb7LKcbGW-VWR
A20: MTC-018 | B20: Criss Cross | C20: Play a line-drawing game on a triangular board and use relationships among vertices, edges, and faces to predict the winner. | D20: Graph Theory | E20: Game Theory; Logic & Proof | F20: planar graphs; Euler’s formula; parity | G20: 2019-06-20 to 2019-06-21 (review) | H20: Summer Institute | I20: =COUNTIF(Offerings!$B$5:$B$145,A20) -> 1 | J20: =IF(COUNTIFS(Offerings!$B$5:$B$145,A20,Offerings!$K$5:$K$145,"Yes")>0,"Yes","No") -> Yes | K20: https://drive.google.com/file/d/1wZBu9JjpnZc-_lNGFN8W4n1F9bUGb0un/view?usp=drivesdk | L20: https://drive.google.com/drive/folders/1NsrdraSpycoqCkhd5WqHbz2EyQAug4eW
A21: MTC-020 | B21: Designing Leadership, Coaching, and Learning Activities | C21: Plan a learning activity by identifying participants, goals, prior knowledge, and evidence of learning, then develop opportunities for active participation. | D21: Teaching & Learning | F21: backward design; coaching; professional learning | G21: 2026-06-15 to 2026-06-18 | H21: Summer Institute | I21: =COUNTIF(Offerings!$B$5:$B$145,A21) -> 1 | J21: =IF(COUNTIFS(Offerings!$B$5:$B$145,A21,Offerings!$K$5:$K$145,"Yes")>0,"Yes","No") -> No | K21: https://docs.google.com/document/d/1thTVuqYvy2QVlGlKgaeSSTik83Pc0ks0/edit?usp=drivesdk&ouid=109901495158487957834&rtpof=true&sd=true | L21: https://drive.google.com/drive/folders/1p_V_zMd7U5Usmmm_pc1ghlzTvB84LP-G
A22: MTC-021 | B22: Desmos: More than Graphing Curves | C22: Connect graphs, equations, and everyday situations, then use Desmos to represent personal experiences with functions and inequalities. | D22: Algebra | E22: Teaching & Learning | F22: Desmos; functions; representations; social justice | G22: 2020-06-26 | H22: Summer Institute | I22: =COUNTIF(Offerings!$B$5:$B$145,A22) -> 1 | J22: =IF(COUNTIFS(Offerings!$B$5:$B$145,A22,Offerings!$K$5:$K$145,"Yes")>0,"Yes","No") -> No | K22: https://drive.google.com/file/d/1Sh_xE5MoDkGr3KBG0lJk_wxq0kbGjDNI/view?usp=drivesdk | L22: https://drive.google.com/drive/folders/1M9dECAjNKbC9FGv_ypUoRPws0u6-LvNK
A23: MTC-022 | B23: Duck Duck Deduce! | C23: Use a circle-elimination game and Eleusis to develop conjectures, infer hidden rules, and practice constructing and critiquing mathematical arguments. | D23: Logic & Proof | E23: Teaching & Learning | F23: Eleusis; Josephus problem; SMP 3; mathematical argument | G23: 2024-12-03 | H23: MTC academic-year session | I23: =COUNTIF(Offerings!$B$5:$B$145,A23) -> 1 | J23: =IF(COUNTIFS(Offerings!$B$5:$B$145,A23,Offerings!$K$5:$K$145,"Yes")>0,"Yes","No") -> No | K23: https://drive.google.com/file/d/1nlSqHlNUYJxRIN2NhdNYJvhPmxM9ZQVc/view?usp=drivesdk | L23: https://drive.google.com/drive/folders/1qQpotvZVNfbISnL2MH9cFcBqC7ggXoq7
A24: MTC-023 | B24: Día de los Muertos and the Mathematics of Musical Groups | C24: Connect Día de los Muertos traditions with mathematical activities, including counting and representing different ways to form musical groups. | D24: Combinatorics | E24: Teaching & Learning | F24: cultural connections; counting; music | G24: 2025-11-04 | H24: MTC academic-year session | I24: =COUNTIF(Offerings!$B$5:$B$145,A24) -> 1 | J24: =IF(COUNTIFS(Offerings!$B$5:$B$145,A24,Offerings!$K$5:$K$145,"Yes")>0,"Yes","No") -> No | K24: https://drive.google.com/file/d/1ccSH5xy64xUybrrpRCfaii4DTrYg7Jkm/view?usp=drivesdk | L24: https://drive.google.com/drive/folders/1MgvnN2dqgEB6Lxpe372rpWqGBQlOUy5g
A25: MTC-025 | B25: Eleusis | C25: Infer a secret rule from legal and illegal card plays, testing and refining conjectures as new evidence becomes available. | D25: Logic & Proof | E25: Number Theory | F25: inductive reasoning; hidden rules; card games | G25: 2019-06-20 to 2019-06-21 (institute window) | H25: Summer Institute | I25: =COUNTIF(Offerings!$B$5:$B$145,A25) -> 1 | J25: =IF(COUNTIFS(Offerings!$B$5:$B$145,A25,Offerings!$K$5:$K$145,"Yes")>0,"Yes","No") -> Yes | K25: https://docs.google.com/presentation/d/1eWTlS74T3knkqT6S_U0QG41FVvl8RVxy/edit?usp=drivesdk&ouid=109901495158487957834&rtpof=true&sd=true | L25: https://drive.google.com/drive/folders/1nc7RfHAErgH-D9djo1jgGfxKw29-k9zM
A26: MTC-026 | B26: Empowering Students Through WODB | C26: Explore and design Which One Doesn’t Belong tasks that support multiple justifications, student ownership, and high expectations. | D26: Teaching & Learning | E26: Logic & Proof | F26: Which One Doesn’t Belong; ICUCARE; student agency; discourse | G26: 2025-06-16 | H26: Summer Institute | I26: =COUNTIF(Offerings!$B$5:$B$145,A26) -> 1 | J26: =IF(COUNTIFS(Offerings!$B$5:$B$145,A26,Offerings!$K$5:$K$145,"Yes")>0,"Yes","No") -> No | K26: https://drive.google.com/file/d/1eqejz5FAttFI-D-_rCoygjtJkY4gr_6E/view?usp=drivesdk | L26: https://drive.google.com/drive/folders/15qE3uYckxLBJmV2cdP55IN15uY3jW_CB
A27: MTC-027 | B27: Estimathon | C27: Work in teams to estimate ranges for real-world quantities and use related estimates to improve accuracy and game strategy. | D27: Number Sense & Arithmetic | E27: Mathematical Modeling | F27: estimation; intervals; collaboration | G27: 2017-10-03 | H27: MTC academic-year session | I27: =COUNTIF(Offerings!$B$5:$B$145,A27) -> 1 | J27: =IF(COUNTIFS(Offerings!$B$5:$B$145,A27,Offerings!$K$5:$K$145,"Yes")>0,"Yes","No") -> No | K27: https://drive.google.com/file/d/0B4cCTfJeL7_dV0lNaHRySThBV1k/view?usp=drivesdk&resourcekey=0-4tLGwO-rngRT5TqyiZh4jw | L27: https://drive.google.com/drive/folders/0B4cCTfJeL7_dYkh0eHhlc1o5dVE?resourcekey=0-mQ9ZVlb8YaF0fKERKMu7-w
A28: MTC-028 | B28: Euler and Hamilton: Two Travelers | C28: Investigate routes that use every road or visit every destination and connect travel problems with graph theory. | D28: Graph Theory | E28: Algorithms & Computing | F28: Euler paths; Hamilton paths; networks | G28: 2020-02-04 (review) | H28: MTC academic-year session | I28: =COUNTIF(Offerings!$B$5:$B$145,A28) -> 1 | J28: =IF(COUNTIFS(Offerings!$B$5:$B$145,A28,Offerings!$K$5:$K$145,"Yes")>0,"Yes","No") -> Yes | K28: https://drive.google.com/file/d/1NUoohDIE7En8mNXJFO17YY8SFLMBh-Aw/view?usp=drivesdk | L28: https://drive.google.com/drive/folders/14m4-qQdf7br8-tagTwB4Q7nAJD-OTZnQ
A29: MTC-029 | B29: Exploding Dots | C29: Use dots-and-boxes machines to model number bases and arithmetic, then extend the representation to polynomial operations and infinite expansions. | D29: Number Sense & Arithmetic | E29: Algebra | F29: place value; number bases; arithmetic; polynomials | G29: 2018-06-18 to 2018-06-19 | H29: Summer Institute | I29: =COUNTIF(Offerings!$B$5:$B$145,A29) -> 1 | J29: =IF(COUNTIFS(Offerings!$B$5:$B$145,A29,Offerings!$K$5:$K$145,"Yes")>0,"Yes","No") -> No | K29: https://docs.google.com/presentation/d/1Xt1UGnUBeJ4dzoaQai64-gyIFavAC_P4/edit?usp=drivesdk&ouid=109901495158487957834&rtpof=true&sd=true | L29: https://drive.google.com/drive/folders/1fTD9nzVBBx-KwkD0_11w5IIrpzxiWWck
A30: MTC-030 | B30: Exploring Traffic Stop Data | C30: Investigate Los Angeles traffic-stop data, compare counts and rates across groups, and consider what additional evidence is needed to interpret disparities. | D30: Probability & Statistics | E30: Mathematical Modeling | F30: CODAP; traffic stops; conditional rates; social justice | G30: 2023-06-22 | H30: Summer Institute | I30: =COUNTIF(Offerings!$B$5:$B$145,A30) -> 1 | J30: =IF(COUNTIFS(Offerings!$B$5:$B$145,A30,Offerings!$K$5:$K$145,"Yes")>0,"Yes","No") -> No | K30: https://docs.google.com/presentation/d/1l0tgXLu1QdG2sz09KWIyXSdB9CKesD0v/edit?usp=drivesdk&ouid=109901495158487957834&rtpof=true&sd=true | L30: https://drive.google.com/drive/folders/1cfYEH3N18lQ0KgAeKUe3Yn0eQ2_KTM96
A31: MTC-031 | B31: Facets of Proof | C31: Compare forms of mathematical reasoning and proof, using tasks to move from observations and conjectures toward convincing general arguments. | D31: Logic & Proof | E31: Teaching & Learning | F31: proof; conjectures; reasoning; mathematical practices | G31: 2019-06-20 to 2019-06-21 (institute window) | H31: Summer Institute | I31: =COUNTIF(Offerings!$B$5:$B$145,A31) -> 1 | J31: =IF(COUNTIFS(Offerings!$B$5:$B$145,A31,Offerings!$K$5:$K$145,"Yes")>0,"Yes","No") -> Yes | K31: https://docs.google.com/presentation/d/1pKYAhcrbgatmOoLS58fDMZghafRnEF7_/edit?usp=drivesdk&ouid=109901495158487957834&rtpof=true&sd=true | L31: https://drive.google.com/drive/folders/1fjql2fMUsHiBMi1aVeM4pZcYt0NRT0OL
A32: MTC-032 | B32: Factoring in Time for Numeracy: Prime Climb | C32: Explore Prime Climb as a game that combines arithmetic, factoring, chance, and strategy to support number fluency. | D32: Number Sense & Arithmetic | E32: Teaching & Learning | F32: number fluency; factoring; Prime Climb | G32: 2018-12-04 | H32: MTC academic-year session | I32: =COUNTIF(Offerings!$B$5:$B$145,A32) -> 1 | J32: =IF(COUNTIFS(Offerings!$B$5:$B$145,A32,Offerings!$K$5:$K$145,"Yes")>0,"Yes","No") -> No | K32: https://drive.google.com/file/d/16ak6R_4SaZE99Gsze3dcCRqK4fT_51pN/view?usp=drivesdk | L32: https://drive.google.com/drive/folders/1ffcjcyAm95Yy8nXxrdPMgVGMrNNJloao
A33: MTC-033 | B33: Fair Voting and Group-Ranking Methods | C33: Compare plurality voting with alternative group-ranking methods and investigate how different definitions of fairness affect election outcomes. | D33: Mathematical Modeling | E33: Logic & Proof | F33: voting theory; rankings; fairness; social choice | G33: 2020-06-25 2024-10-01 | H33: MTC academic-year session; Summer Institute | I33: =COUNTIF(Offerings!$B$5:$B$145,A33) -> 2 | J33: =IF(COUNTIFS(Offerings!$B$5:$B$145,A33,Offerings!$K$5:$K$145,"Yes")>0,"Yes","No") -> No | K33: https://drive.google.com/file/d/1_G-doR9-mrjYP-6QWYDMwIEsKJ-EM9Bu/view?usp=drivesdk | L33: https://drive.google.com/drive/folders/1jr59l3Nt-latBDxjDcg6UgkIzhqG8Jv9
A34: MTC-034 | B34: Flipping the Script: Reclaiming Mathematics for Our Students and Ourselves | C34: Explore an equity-focused approach to reclaiming mathematics for students and teachers, with discussion and lesson-planning connections. | D34: Teaching & Learning | F34: equity; student agency; social justice | G34: 2020-06-22 | H34: Summer Institute | I34: =COUNTIF(Offerings!$B$5:$B$145,A34) -> 1 | J34: =IF(COUNTIFS(Offerings!$B$5:$B$145,A34,Offerings!$K$5:$K$145,"Yes")>0,"Yes","No") -> Yes | K34: https://docs.google.com/document/d/1MU72dj7yVBt8j7hlae9ghGnPc6Dz3vmIQFpOM_nm71k/edit?usp=drivesdk | L34: https://drive.google.com/drive/folders/1TR-rQ5baZ9czW3kQE8Y527uOZJ4PG-0s
A35: MTC-035 | B35: Framework for All: A Vision for Teaching and Learning | C35: Examine the framework’s three dimensions of systemic change and five components of equitable teaching, with applications to classrooms and coaching. | D35: Teaching & Learning | F35: California Mathematics Framework; equity; coaching | G35: 2026-06-16 | H35: Summer Institute | I35: =COUNTIF(Offerings!$B$5:$B$145,A35) -> 1 | J35: =IF(COUNTIFS(Offerings!$B$5:$B$145,A35,Offerings!$K$5:$K$145,"Yes")>0,"Yes","No") -> No | K35: https://docs.google.com/presentation/d/1LaKKeZC-iN40iNDtyXvu56n75MUrDwQI/edit?usp=drivesdk&ouid=109901495158487957834&rtpof=true&sd=true | L35: https://drive.google.com/drive/folders/1M33DXkdcTbmOGg8w4ljAmGfdoj7i8RRQ
A36: MTC-037 | B36: Getting Nim-ble with Binary | C36: Investigate winning strategies in Nim and how starting configurations and rule changes connect the game with binary arithmetic. | D36: Game Theory | E36: Number Theory | F36: Nim; binary; winning positions | G36: 2019-05-07 | H36: MTC academic-year session | I36: =COUNTIF(Offerings!$B$5:$B$145,A36) -> 1 | J36: =IF(COUNTIFS(Offerings!$B$5:$B$145,A36,Offerings!$K$5:$K$145,"Yes")>0,"Yes","No") -> No | K36: https://drive.google.com/file/d/1LmYLoppKA9ocXHlpg0I5khoTcvwL6DyI/view?usp=drivesdk | L36: https://drive.google.com/drive/folders/1oGJIHA5ZxR875CYuluh6RfpoRAxKMTrl
A37: MTC-038 | B37: Graph Talks | C37: Use meaningful graphs to elicit student observations, questions, and mathematical reasoning while discussing the social contexts represented by data. | D37: Teaching & Learning | E37: Probability & Statistics | F37: graph talks; data visualization; social justice; discussion | G37: 2022-06-21 2023-06-20 2023-06-21 | H37: Summer Institute | I37: =COUNTIF(Offerings!$B$5:$B$145,A37) -> 3 | J37: =IF(COUNTIFS(Offerings!$B$5:$B$145,A37,Offerings!$K$5:$K$145,"Yes")>0,"Yes","No") -> No | K37: https://docs.google.com/presentation/d/1T1zOtCkQU_-Zb9bVvNtdICIVOv_v73ZS/edit?usp=drivesdk&ouid=109901495158487957834&rtpof=true&sd=true | L37: https://drive.google.com/drive/folders/1hDwdu80o8G_uXserSpBBqKXl4dJBQL1_
A38: MTC-039 | B38: Guppies, Goldfish and the Golden Ratio | C38: Play a two-pile take-away game and investigate how safe positions, number patterns, and the golden ratio reveal winning strategies. | D38: Game Theory | E38: Number Theory | F38: Wythoff’s game; golden ratio; winning positions | G38: 2025-09-02 | H38: MTC academic-year session | I38: =COUNTIF(Offerings!$B$5:$B$145,A38) -> 1 | J38: =IF(COUNTIFS(Offerings!$B$5:$B$145,A38,Offerings!$K$5:$K$145,"Yes")>0,"Yes","No") -> No | K38: https://drive.google.com/file/d/1ZrqtsJmZ_sj1Xm1RNL6B6KnIKHsJtzOD/view?usp=drivesdk | L38: https://drive.google.com/drive/folders/1khQvS5_iRyU4DulxZAVqDj2DPrWzc_GA
A39: MTC-040 | B39: Harmonic Numbers | C39: Explore numbers of the form 2^a × 3^b, investigate their possible differences, and connect the questions with musical ratios and the abc conjecture. | D39: Number Theory | F39: harmonic numbers; differences; abc conjecture | G39: 2019-12-03 | H39: MTC academic-year session | I39: =COUNTIF(Offerings!$B$5:$B$145,A39) -> 1 | J39: =IF(COUNTIFS(Offerings!$B$5:$B$145,A39,Offerings!$K$5:$K$145,"Yes")>0,"Yes","No") -> No | K39: https://drive.google.com/file/d/14NMNxZXO05cJLv0l_H-OyJCi0VUlGaVL/view?usp=drivesdk | L39: https://drive.google.com/drive/folders/1QngmjBRVRDmBrUxQpDi4INur_f1rfZUq
A40: MTC-041 | B40: How Generative AI Works and How It Can Work for You | C40: Explore the mathematics behind generative AI, practice prompt design, and examine classroom uses and limitations of AI tools. | D40: Teaching & Learning | E40: Algorithms & Computing | F40: generative AI; large language models; prompt design | G40: 2025-09-16 | H40: LIFT | I40: =COUNTIF(Offerings!$B$5:$B$145,A40) -> 1 | J40: =IF(COUNTIFS(Offerings!$B$5:$B$145,A40,Offerings!$K$5:$K$145,"Yes")>0,"Yes","No") -> No | K40: https://drive.google.com/file/d/1HYmRyKHHLjUH1plonTNwwYzKKR3XnQ0w/view?usp=drivesdk | L40: https://drive.google.com/drive/folders/1CceKEqM8hNhsHav8l4tEptIcttER7HG9
A41: MTC-042 | B41: I Walk the Line(s) | C41: Count routes through a city laid out on a square grid, then investigate how restrictions and obstacles change the possible paths. | D41: Combinatorics | F41: grid paths; counting; obstacles; Catalan numbers | G41: 2022-02-01 2026-05-05 | H41: MTC academic-year session | I41: =COUNTIF(Offerings!$B$5:$B$145,A41) -> 2 | J41: =IF(COUNTIFS(Offerings!$B$5:$B$145,A41,Offerings!$K$5:$K$145,"Yes")>0,"Yes","No") -> No | K41: https://drive.google.com/file/d/1bUV6IoSvVROkVKEdK5lKC5biTV5Q8TTe/view?usp=drivesdk | L41: https://drive.google.com/drive/folders/1JL7xZB4YFofEOWhY-ZSCobR_vBFLc-gZ
...

Sheet Offerings
A1: Documented offerings
A2: 148 offering records . 28 flagged for review . Start/end dates may be candidate dates or institute windows; read Date status
A4: Offering ID | B4: Session ID | C4: Session title | D4: Start date | E4: End date | F4: Date label | G4: Date status | H4: Program | I4: Archive context | J4: Facilitator / presenter | K4: Review needed | L4: Source notes / review details | M4: Source URL 1 | N4: Source URL 2 | O4: Resource folder URL
A5: OFR-001 | B5: MTC-084 | C5: Pancake Sorting and Recursion | D5: 42619 | E5: 42619 | F5: 2016-09-06 | G5: Exact date | H5: MTC academic-year session | I5: 2016-2017 Academic Year/9/6/16 Pancake Sorting | K5: No | M5: https://drive.google.com/file/d/0B4cCTfJeL7_deUdjclQ3NnFELVU/view?usp=drivesdk&resourcekey=0-zp3Cn9a3fXHo_C2g_YC3cw | O5: https://drive.google.com/drive/folders/0B4cCTfJeL7_dQ2RycmJVeTNETXM?resourcekey=0-4K6CIC7x0R0waYq99bkWGA
A6: OFR-002 | B6: MTC-090 | C6: Rational Tangle Dance | D6: 42647 | E6: 42647 | F6: 2016-10-04 | G6: Exact date | H6: MTC academic-year session | I6: 2016-2017 Academic Year/10/4/16 Rational Tangles | K6: No | M6: https://drive.google.com/file/d/0B4cCTfJeL7_dVUtKWVJXMnA5XzQ/view?usp=drivesdk&resourcekey=0-6BQhmPR9EvS9WJPbXzkZiA | O6: https://drive.google.com/drive/folders/0B4cCTfJeL7_dU1FKRzl0RldhR0U?resourcekey=0-Y0algVj--3lZVPKkuZKJiQ
A7: OFR-003 | B7: MTC-116 | C7: The Mad Veterinarian | D7: 42675 | E7: 42675 | F7: 2016-11-01 | G7: Exact date | H7: MTC academic-year session | I7: 2016-2017 Academic Year/11/1/16 Mad Vet | K7: No | M7: https://drive.google.com/file/d/0B4cCTfJeL7_dcUF3dHJHWjJiMEE/view?usp=drivesdk&resourcekey=0-81akf2SWjep3EUPUzYf7mg | O7: https://drive.google.com/drive/folders/0B4cCTfJeL7_dZ3YwX2JjODYxVVk?resourcekey=0-e5oGqFPne975XL1jVl2yRg
A8: OFR-004 | B8: MTC-087 | C8: Pirates, Prisoners, and Chicken: An Introduction to Game Theory | D8: 42710 | E8: 42710 | F8: 2016-12-06 | G8: Exact date | H8: MTC academic-year session | I8: 2016-2017 Academic Year/12/6/16 Game Theory | K8: No | M8: https://drive.google.com/file/d/0B4cCTfJeL7_dZ0d4eFRvY0M2WFU/view?usp=drivesdk&resourcekey=0-BU-CIxJ-KiHzrpFxXsS3uA | O8: https://drive.google.com/drive/folders/0B4cCTfJeL7_dOFBFa3FZZ3p3X2s?resourcekey=0-3nvbz4Z7QcO8Jp0kPrED0Q
A9: OFR-005 | B9: MTC-096 | C9: SET: The Mathematics Behind the Game | D9: 42773 | E9: 42773 | F9: 2017-02-07 (review) | G9: Date conflict | H9: MTC academic-year session | I9: 2016-2017 Academic Year/2/7/17 Set | K9: Yes | L9: Flyer says 2016-02-07; academic-year folder places the session in 2017. Date shown follows folder context; confirm before publication. | M9: https://drive.google.com/file/d/0B4cCTfJeL7_dQ2lLeDdMUDhwX28/view?usp=drivesdk&resourcekey=0-WVYtZLMYQXEHOqfrY_cTog | O9: https://drive.google.com/drive/folders/0B4cCTfJeL7_ddmlxWS1KMEhRUU0?resourcekey=0-OSSepIY-DO-yW5nAxaOcUg
A10: OFR-006 | B10: MTC-049 | C10: KenKen | D10: 42801 | E10: 42801 | F10: 2017-03-07 (review) | G10: Date conflict | H10: MTC academic-year session | I10: 2016-2017 Academic Year/3/7/17 KenKen | K10: Yes | L10: Flyer says 2016-03-07; academic-year folder places the session in 2017. Date shown follows folder context; confirm before publication. | M10: https://drive.google.com/file/d/0B4cCTfJeL7_dUlREbmJoWGpoRlU/view?usp=drivesdk&resourcekey=0-2KQz8LJ2bXF_iO3B4_-4tg | O10: https://drive.google.com/drive/folders/0B4cCTfJeL7_dNzh2OXc3WDN5Tjg?resourcekey=0-6YR3U00KQXCHW6GbAQ7Q7w
A11: OFR-007 | B11: MTC-055 | C11: Liar’s Bingo | D11: 42829 | E11: 42829 | F11: 2017-04-04 (review) | G11: Date conflict | H11: MTC academic-year session | I11: 2016-2017 Academic Year/4/4/17 Liar's Bingo | K11: Yes | L11: Flyer says 2016-04-04; academic-year folder places the session in 2017. Date shown follows folder context; confirm before publication. | M11: https://drive.google.com/file/d/0B4cCTfJeL7_dczlEMzB2eGQ5YVk/view?usp=drivesdk&resourcekey=0-GCGp3Qs2y9W6daypRLoWtA | O11: https://drive.google.com/drive/folders/0B4cCTfJeL7_dWWMzbGxOSjVGdWc?resourcekey=0-_FeKZxpz7-puqnxrmu6Z9A
A12: OFR-008 | B12: MTC-104 | C12: Spot It! | D12: 42857 | E12: 42857 | F12: 2017-05-02 (review) | G12: Date conflict | H12: MTC academic-year session | I12: 2016-2017 Academic Year/5/2/17 Spot It! | K12: Yes | L12: Flyer says 2016-05-02; academic-year folder places the session in 2017. Date shown follows folder context; confirm before publication. | M12: https://drive.google.com/file/d/0B4cCTfJeL7_dQUQ3eU5sOE5MWUU/view?usp=drivesdk&resourcekey=0-Cw1xQYQCqNsv5bN4o85e6w | O12: https://drive.google.com/drive/folders/0B4cCTfJeL7_dbUI1cU4yc3hVblU?resourcekey=0-54WnQLLZfcFpfgeyMwqqEw
A13: OFR-010 | B13: MTC-045 | C13: Instant Insanity | D13: 42901 | E13: 42902 | F13: 2017-06-15 to 2017-06-16 (institute window) | G13: Institute window | H13: Summer Institute | I13: 2017 Summer Institute | K13: Yes | L13: Individual session day is not established; slide author is Judith Covington, not verified as the local facilitator. | M13: https://docs.google.com/presentation/d/0B4cCTfJeL7_dZ084MGZNUjVBU1E/edit?usp=drivesdk&ouid=109901495158487957834&resourcekey=0-xqQaukkaqbnIwZhtqkr3HQ&rtpof=true&sd=true | N13: https://drive.google.com/file/d/0B4cCTfJeL7_dU3lfY2t4ckNZQ3M/view?usp=drivesdk&resourcekey=0-mgNytrTm-j1DMeP0R_Ki6w | O13: https://drive.google.com/drive/folders/0B4cCTfJeL7_dQTJaNFc5empWbUE?resourcekey=0-8hWfh9_udgJ8jFMROirwEg
A14: OFR-011 | B14: MTC-057 | C14: Logic: Knights and Knaves | D14: 42901 | E14: 42902 | F14: 2017-06-15 to 2017-06-16 (institute window) | G14: Institute window | H14: Summer Institute | I14: 2017 Summer Institute | K14: Yes | L14: Individual session day is not established. Slides credit Martha Rojas. | M14: https://docs.google.com/presentation/d/0B2XvpmARE9ZbMnZCM0ZOaHZXSVk/edit?usp=drivesdk&ouid=109901495158487957834&resourcekey=0-V7nKYNXuHYTwHhbaPrZV6w&rtpof=true&sd=true | N14: https://drive.google.com/file/d/0B4cCTfJeL7_dU3lfY2t4ckNZQ3M/view?usp=drivesdk&resourcekey=0-mgNytrTm-j1DMeP0R_Ki6w | O14: https://drive.google.com/drive/folders/0B4cCTfJeL7_dWWlYb3JRTVljWlU?resourcekey=0-NwX1MEHlBgX_Rxr44Y1iBQ
A15: OFR-012 | B15: MTC-062 | C15: Mastermind | D15: 42901 | E15: 42902 | F15: 2017-06-15 to 2017-06-16 (institute window) | G15: Institute window | H15: Summer Institute | I15: 2017 Summer Institute | K15: Yes | L15: Individual session day is not established. | M15: https://docs.google.com/presentation/d/0B4cCTfJeL7_dbkR1d0RQeHRMclU/edit?usp=drivesdk&ouid=109901495158487957834&resourcekey=0-qaLSVqn8XKSsNH4sKGV55g&rtpof=true&sd=true | N15: https://drive.google.com/file/d/0B4cCTfJeL7_dU3lfY2t4ckNZQ3M/view?usp=drivesdk&resourcekey=0-mgNytrTm-j1DMeP0R_Ki6w | O15: https://drive.google.com/drive/folders/0B4cCTfJeL7_dTHBkS1RrSkdGa1E?resourcekey=0-t_6NCUKHfrRprA1_i9yyhw
A16: OFR-013 | B16: MTC-080 | C16: Number Bracelets | D16: 42901 | E16: 42902 | F16: 2017-06-15 to 2017-06-16 (institute window) | G16: Institute window | H16: Summer Institute | I16: 2017 Summer Institute | K16: Yes | L16: Folder identifies a Number Bracelets mini-session; local PDF/PPT text was unavailable. Description uses the matching 2023 session flyer. Individual day is not established. | M16: https://drive.google.com/file/d/0B4cCTfJeL7_dZEszNWJvRHBDQkU/view?usp=drivesdk&resourcekey=0-JEkHg4pkfRvfDuTq1EmA7g | N16: https://drive.google.com/file/d/0B4cCTfJeL7_dU3lfY2t4ckNZQ3M/view?usp=drivesdk&resourcekey=0-mgNytrTm-j1DMeP0R_Ki6w | O16: https://drive.google.com/drive/folders/0B4cCTfJeL7_dU2JKWnFJcGtBY00?resourcekey=0-FP1TbLBlmig7a_ncKTRKmg
A17: OFR-014 | B17: MTC-103 | C17: Spaghetti Tower Challenge | D17: 42901 | E17: 42902 | F17: 2017-06-15 to 2017-06-16 (institute window) | G17: Institute window | H17: Summer Institute | I17: 2017 Summer Institute | K17: Yes | L17: Included as a named institute activity; individual day is not established. | M17: https://docs.google.com/presentation/d/0B4cCTfJeL7_dNkFpWHhUbkk5cmM/edit?usp=drivesdk&ouid=109901495158487957834&resourcekey=0-14wM74J9lM5YAVbPFV4nyA&rtpof=true&sd=true | N17: https://drive.google.com/file/d/0B4cCTfJeL7_dU3lfY2t4ckNZQ3M/view?usp=drivesdk&resourcekey=0-mgNytrTm-j1DMeP0R_Ki6w | O17: https://drive.google.com/drive/folders/0B4cCTfJeL7_dWTVUcFFkV2tlRkk?resourcekey=0-HN2srsoL-ck5T3_rtb41LA
A18: OFR-015 | B18: MTC-106 | C18: Sprouts | D18: 42901 | E18: 42902 | F18: 2017-06-15 to 2017-06-16 (institute window) | G18: Institute window | H18: Summer Institute | I18: 2017 Summer Institute | K18: Yes | L18: Individual session day is not established. | M18: https://docs.google.com/presentation/d/0B4cCTfJeL7_dUGgtc2hVRVZkZFU/edit?usp=drivesdk&ouid=109901495158487957834&resourcekey=0-xyg98UR1GYtUjh9gnA0xIg&rtpof=true&sd=true | N18: https://drive.google.com/file/d/0B4cCTfJeL7_dU3lfY2t4ckNZQ3M/view?usp=drivesdk&resourcekey=0-mgNytrTm-j1DMeP0R_Ki6w | O18: https://drive.google.com/drive/folders/0B4cCTfJeL7_dcFp4bFRZSFpnNDg?resourcekey=0-hSfkHFOkkiJTtdq-rI2V5Q
A19: OFR-016 | B19: MTC-100 | C19: Simon Says, Four Gallons | D19: 42983 | E19: 42983 | F19: 2017-09-05 | G19: Exact date | H19: MTC academic-year session | I19: 2017-2018 Academic Year/9/5/17 Simon Says, Four Gallons | K19: No | M19: https://drive.google.com/file/d/0B4cCTfJeL7_deVFiWDRMT1VQYmc/view?usp=drivesdk&resourcekey=0-8EUWjRObcmI30hRFwB6oZg | O19: https://drive.google.com/drive/folders/0B4cCTfJeL7_dUFNwTFBrNUU4VzA?resourcekey=0-96gg3J2fV_f4hY50lKOCkg
A20: OFR-017 | B20: MTC-027 | C20: Estimathon | D20: 43011 | E20: 43011 | F20: 2017-10-03 | G20: Exact date | H20: MTC academic-year session | I20: 2017-2018 Academic Year/10/3/17 Estimathon | K20: No | M20: https://drive.google.com/file/d/0B4cCTfJeL7_dV0lNaHRySThBV1k/view?usp=drivesdk&resourcekey=0-4tLGwO-rngRT5TqyiZh4jw | O20: https://drive.google.com/drive/folders/0B4cCTfJeL7_dYkh0eHhlc1o5dVE?resourcekey=0-mQ9ZVlb8YaF0fKERKMu7-w
A21: OFR-018 | B21: MTC-014 | C21: Candy Sharing | D21: 43046 | E21: 43046 | F21: 2017-11-07 | G21: Exact date | H21: MTC academic-year session | I21: 2017-2018 Academic Year/11/7/17 Candy Sharing | K21: No | M21: https://drive.google.com/file/d/0B4cCTfJeL7_dNG1SRGJIUWh4R2c/view?usp=drivesdk&resourcekey=0-jEyNsfAltNj9lA6QZChKPQ | O21: https://drive.google.com/drive/folders/0B4cCTfJeL7_demd3d3RFTkZKWnM?resourcekey=0-MzT-jVW9rtLCFP_7rXBvcw
A22: OFR-019 | B22: MTC-048 | C22: Is Santa Secretly Deranged? | D22: 43074 | E22: 43074 | F22: 2017-12-05 | G22: Exact date | H22: MTC academic-year session | I22: 2017-2018 Academic Year/12/5/17 Secret Santa | K22: No | M22: https://drive.google.com/file/d/0B4cCTfJeL7_dRGtKNnNWdTZYdDQ/view?usp=drivesdk&resourcekey=0-nGy0YI7Lwf594ydSovumNg | O22: https://drive.google.com/drive/folders/0B4cCTfJeL7_dMXY5aFFEVmV4WWM?resourcekey=0-kjwEUe_Jp8A26HRYrpu0_g
A23: OFR-020 | B23: MTC-086 | C23: Pick Connects the Dots | D23: 43137 | E23: 43137 | F23: 2018-02-06 | G23: Resolved source typo | H23: MTC academic-year session | I23: 2017-2018 Academic Year/2/6/18 Pick Connects the Dots | K23: No | L23: Flyer says 2017-02-06; academic-year folder places the session in 2018. Date shown is corroborated by the dated folder and the 2017–2018 annual meeting schedule. | M23: https://drive.google.com/file/d/1R1gYmeYW9Lj7iffE529TqyvGBsKE07mJ/view?usp=drivesdk | N23: https://drive.google.com/file/d/0B4cCTfJeL7_ddFdsUVdRLXlaTzQ/view?usp=drivesdk&resourcekey=0-JM9t5EGhZrOqAE-8IEEG4g | O23: https://drive.google.com/drive/folders/1q_2vVslIW9JqR0NSnnPxMRve8Qwb7L4m
A24: OFR-021 | B24: MTC-114 | C24: The Game of Hex | D24: 43165 | E24: 43165 | F24: 2018-03-06 | G24: Resolved source typo | H24: MTC academic-year session | I24: 2017-2018 Academic Year/3/6/18 Hex | K24: No | L24: Flyer says 2017-03-06; academic-year folder places the session in 2018. Date shown is corroborated by the dated folder and the 2017–2018 annual meeting schedule. | M24: https://drive.google.com/file/d/1bLa7gfa8xUVahh1Gr22CDvwwh9Pj1nge/view?usp=drivesdk | N24: https://drive.google.com/file/d/0B4cCTfJeL7_ddFdsUVdRLXlaTzQ/view?usp=drivesdk&resourcekey=0-JM9t5EGhZrOqAE-8IEEG4g | O24: https://drive.google.com/drive/folders/1TCrLedo3dh09m9uQ3HBEV1-k7I6qxZZf
A25: OFR-023 | B25: MTC-050 | C25: Knot Mosaics | D25: 43221 | E25: 43221 | F25: 2018-05-01 | G25: Exact date | H25: MTC academic-year session | I25: 2017-2018 Academic Year/5/1/18 Knot Mosaics | K25: No | M25: https://drive.google.com/file/d/11ZpvXPWejLT5th3HJ3hSWalPALNrBgMz/view?usp=drivesdk | O25: https://drive.google.com/drive/folders/1jnKOroAXawrv7jPNAbeqiP_dv2ScX-o2
A26: OFR-024 | B26: MTC-004 | C26: Alternate Algorithms | D26: 43269 | E26: 43272 | F26: 2018-06-18 to 2018-06-21 (institute window) | G26: Institute window | H26: Summer Institute | I26: 2018 Summer Institute | K26: Yes | L26: Individual session day is not established. Slides credit Part I to Martha Rojas and Part II to Dr. Jones. | M26: https://docs.google.com/presentation/d/1u6vBmLM7voR7AKzROirAZsQji_7M82HC/edit?usp=drivesdk&ouid=109901495158487957834&rtpof=true&sd=true | N26: https://docs.google.com/presentation/d/1w6zbxZ-IP-d8JIvt92fKb847qBwcJWLG/edit?usp=drivesdk&ouid=109901495158487957834&rtpof=true&sd=true | O26: https://drive.google.com/drive/folders/1SdYWc2admzVtcf9FW5D6I12sTV-2Ivi4
A27: OFR-026 | B27: MTC-029 | C27: Exploding Dots | D27: 43269 | E27: 43270 | F27: 2018-06-18 to 2018-06-19 | G27: Multi-day session | H27: Summer Institute | I27: 2018 Summer Institute | K27: No | L27: Part 1 slides specify June 18; Part 2 specifies June 19. Treated as one two-part offering. | M27: https://docs.google.com/presentation/d/1Xt1UGnUBeJ4dzoaQai64-gyIFavAC_P4/edit?usp=drivesdk&ouid=109901495158487957834&rtpof=true&sd=true | N27: https://docs.google.com/presentation/d/1t8J3ddja7Gsl0gzR603MUG_G9H8HWMHH/edit?usp=drivesdk&ouid=109901495158487957834&rtpof=true&sd=true | O27: https://drive.google.com/drive/folders/1fTD9nzVBBx-KwkD0_11w5IIrpzxiWWck
A28: OFR-027 | B28: MTC-082 | C28: Number Sense and Number Talks | D28: 43269 | E28: 43272 | F28: 2018-06-18 to 2018-06-21 (institute window) | G28: Institute window | H28: Summer Institute | I28: 2018 Summer Institute | K28: Yes | L28: Institute overview dates the event June 18–21; the individual session date is not explicit. | M28: https://docs.google.com/presentation/d/1w6zbxZ-IP-d8JIvt92fKb847qBwcJWLG/edit?usp=drivesdk&ouid=109901495158487957834&rtpof=true&sd=true | O28: https://drive.google.com/drive/folders/11FfjTUKh-FPQhCcOhtIda6V1nSSo_Z9J
A29: OFR-028 | B29: MTC-123 | C29: Tie Folding | D29: 43269 | E29: 43272 | F29: 2018-06-18 to 2018-06-21 (institute window) | G29: Institute window | H29: Summer Institute | I29: 2018 Summer Institute | K29: Yes | L29: Individual session day is not established. | M29: https://docs.google.com/presentation/d/1qex5opjxGqGC-i2oN65td994Ro2i69cr/edit?usp=drivesdk&ouid=109901495158487957834&rtpof=true&sd=true | N29: https://docs.google.com/presentation/d/1w6zbxZ-IP-d8JIvt92fKb847qBwcJWLG/edit?usp=drivesdk&ouid=109901495158487957834&rtpof=true&sd=true | O29: https://drive.google.com/drive/folders/1aNQ_FDnyCco1U3pa7SlDA983Xpvr33rR
A30: OFR-029 | B30: MTC-131 | C30: What I Learned About Sharing Long After Kindergarten | D30: 43347 | E30: 43347 | F30: 2018-09-04 | G30: Exact date | H30: MTC academic-year session | I30: 2018-2019 Academic Year/9/4 Fair Sharing | K30: No | M30: https://drive.google.com/file/d/1nsXDgel4Pb_3ipjtnjLBgSKMJJ-FfaQc/view?usp=drivesdk | O30: https://drive.google.com/drive/folders/1yOpm_cASa4HBAA6QgUjQdONtHIGUPE_n
A31: OFR-030 | B31: MTC-135 | C31: Winning the Lottery | D31: 43375 | E31: 43375 | F31: 2018-10-02 | G31: Exact date | H31: MTC academic-year session | I31: 2018-2019 Academic Year/10/2 Lottery | K31: No | M31: https://drive.google.com/file/d/18i5vhFOo7l9IdpyytXgObFTv-3tfjAKr/view?usp=drivesdk | O31: https://drive.google.com/drive/folders/1wXZbh9f63Wpej9tlYk4UVJ-kr04eYgtk
A32: OFR-031 | B32: MTC-010 | C32: Blokus and Polyominoes | D32: 43410 | E32: 43410 | F32: 2018-11-06 | G32: Year from academic-year folder | H32: MTC academic-year session | I32: 2018-2019 Academic Year/11/6 Blokus | K32: No | M32: https://drive.google.com/file/d/11LMWsczRyxmNkLaP_2Zb_5QISDRARhAM/view?usp=drivesdk | O32: https://drive.google.com/drive/folders/1i6fFH73dedn7uE3D5CrxC0mC5dTf-zL8
A33: OFR-032 | B33: MTC-032 | C33: Factoring in Time for Numeracy: Prime Climb | D33: 43438 | E33: 43438 | F33: 2018-12-04 | G33: Year from academic-year folder | H33: MTC academic-year session | I33: 2018-2019 Academic Year/12/4 Prime Climb | K33: No | M33: https://drive.google.com/file/d/16ak6R_4SaZE99Gsze3dcCRqK4fT_51pN/view?usp=drivesdk | O33: https://drive.google.com/drive/folders/1ffcjcyAm95Yy8nXxrdPMgVGMrNNJloao
A34: OFR-033 | B34: MTC-063 | C34: Match or No Match | D34: 43501 | E34: 43501 | F34: 2019-02-05 | G34: Year from academic-year folder | H34: MTC academic-year session | I34: 2018-2019 Academic Year/2/5 Match or No Match | K34: No | M34: https://drive.google.com/file/d/1uC4fIii10Gq-tSJ5Dwhw5_m51EwmJBEC/view?usp=drivesdk | O34: https://drive.google.com/drive/folders/1hAGkv8rqxLUASObqaWlFU_gVs-0zwUHv
A35: OFR-034 | B35: MTC-110 | C35: Symmetry and Algebra | D35: 43529 | E35: 43529 | F35: 2019-03-05 | G35: Year from academic-year folder | H35: MTC academic-year session | I35: 2018-2019 Academic Year/3/5 Symmetry and Algebra | K35: No | M35: https://drive.google.com/file/d/1xszrpVkaqbfBuJGGqZEcdB6l5hACiwzj/view?usp=drivesdk | O35: https://drive.google.com/drive/folders/1gkpHpNj4NZSQS1hdGddoKnZAOpmh2KUX
A36: OFR-035 | B36: MTC-037 | C36: Getting Nim-ble with Binary | D36: 43592 | E36: 43592 | F36: 2019-05-07 | G36: Year from academic-year folder | H36: MTC academic-year session | I36: 2018-2019 Academic Year/5/7 Nim | K36: No | M36: https://drive.google.com/file/d/1LmYLoppKA9ocXHlpg0I5khoTcvwL6DyI/view?usp=drivesdk | O36: https://drive.google.com/drive/folders/1oGJIHA5ZxR875CYuluh6RfpoRAxKMTrl
A37: OFR-037 | B37: MTC-018 | C37: Criss Cross | D37: 43636 | E37: 43637 | F37: 2019-06-20 to 2019-06-21 (review) | G37: Date conflict | H37: Summer Institute | I37: 2019 Summer Institute | K37: Yes | L37: Institute flyer gives June 20–21; session slides say June 19. Individual date needs confirmation. | M37: https://drive.google.com/file/d/1wZBu9JjpnZc-_lNGFN8W4n1F9bUGb0un/view?usp=drivesdk | N37: https://drive.google.com/file/d/18IAEnpI3zxkzzDaN-RwC1Odal0ARUM-i/view?usp=drivesdk | O37: https://drive.google.com/drive/folders/1NsrdraSpycoqCkhd5WqHbz2EyQAug4eW
A38: OFR-038 | B38: MTC-025 | C38: Eleusis | D38: 43636 | E38: 43637 | F38: 2019-06-20 to 2019-06-21 (institute window) | G38: Institute window | H38: Summer Institute | I38: 2019 Summer Institute | K38: Yes | L38: Individual session day is not established. Eleusis also appears within Duck Duck Deduce in 2024. | M38: https://docs.google.com/presentation/d/1eWTlS74T3knkqT6S_U0QG41FVvl8RVxy/edit?usp=drivesdk&ouid=109901495158487957834&rtpof=true&sd=true | N38: https://drive.google.com/file/d/18IAEnpI3zxkzzDaN-RwC1Odal0ARUM-i/view?usp=drivesdk | O38: https://drive.google.com/drive/folders/1nc7RfHAErgH-D9djo1jgGfxKw29-k9zM
A39: OFR-039 | B39: MTC-031 | C39: Facets of Proof | D39: 43636 | E39: 43637 | F39: 2019-06-20 to 2019-06-21 (institute window) | G39: Institute window | H39: Summer Institute | I39: 2019 Summer Institute | K39: Yes | L39: Individual session day is not established. | M39: https://docs.google.com/presentation/d/1pKYAhcrbgatmOoLS58fDMZghafRnEF7_/edit?usp=drivesdk&ouid=109901495158487957834&rtpof=true&sd=true | N39: https://drive.google.com/file/d/18IAEnpI3zxkzzDaN-RwC1Odal0ARUM-i/view?usp=drivesdk | O39: https://drive.google.com/drive/folders/1fjql2fMUsHiBMi1aVeM4pZcYt0NRT0OL
A40: OFR-040 | B40: MTC-044 | C40: Inductive Reasoning with Geoboards | D40: 43636 | E40: 43637 | F40: 2019-06-20 to 2019-06-21 (institute window) | G40: Institute window | H40: Summer Institute | I40: 2019 Summer Institute | K40: Yes | L40: Individual session day is not established. | M40: https://docs.google.com/presentation/d/1TMow9UBVdxIhyPxYmk4QKFf2aPfA39kd45XcXvdJ71w/edit?usp=drivesdk | N40: https://drive.google.com/file/d/18IAEnpI3zxkzzDaN-RwC1Odal0ARUM-i/view?usp=drivesdk | O40: https://drive.google.com/drive/folders/1rCzj4dRC4_nPVNUpFQC8srEsaJOrEUFN
A41: OFR-041 | B41: MTC-115 | C41: The Josephus Problem | D41: 43636 | E41: 43637 | F41: 2019-06-20 to 2019-06-21 (institute window) | G41: Institute window | H41: Summer Institute | I41: 2019 Summer Institute | K41: Yes | L41: Individual session day is not established. | M41: https://docs.google.com/presentation/d/1kYmasiSFiBZJEIJbKX32WN3SQg_o9oxJ/edit?usp=drivesdk&ouid=109901495158487957834&rtpof=true&sd=true | N41: https://drive.google.com/file/d/18IAEnpI3zxkzzDaN-RwC1Odal0ARUM-i/view?usp=drivesdk | O41: https://drive.google.com/drive/folders/1ptFLSF9Fq1c5uVTikawl8OslpUu3nYAX
...

Sheet Resources
A1: Resource inventory
A2: 586 files . Full folder paths retained . Blank session/offering IDs indicate a resource not assigned to a specific session
A4: Resource title | B4: File type | C4: Resource role | D4: Archive path | E4: Session IDs | F4: Offering IDs | G4: Review coverage | H4: Resource URL | I4: Drive file ID
A5: MTC 10-4 Meeting Flyer.pdf | B5: PDF | C5: Agenda / announcement / institute support | D5: 2016-2017 Academic Year/10/4/16 Rational Tangles/MTC 10-4 Meeting Flyer.pdf | E5: MTC-090 | F5: OFR-002 | G5: Text reviewed | H5: https://drive.google.com/file/d/0B4cCTfJeL7_dVUtKWVJXMnA5XzQ/view?usp=drivesdk&resourcekey=0-6BQhmPR9EvS9WJPbXzkZiA | I5: 0B4cCTfJeL7_dVUtKWVJXMnA5XzQ
A6: Rational Tangle.pdf | B6: PDF | C6: Session or supporting resource | D6: 2016-2017 Academic Year/10/4/16 Rational Tangles/Rational Tangle.pdf | E6: MTC-090 | F6: OFR-002 | G6: Metadata inventoried | H6: https://drive.google.com/file/d/0B4cCTfJeL7_dZ1g5OHV2b0ppRE0/view?usp=drivesdk&resourcekey=0-gFEEHzqZZLUYISQVf2ElqQ | I6: 0B4cCTfJeL7_dZ1g5OHV2b0ppRE0
A7: Rational Tangles 10-4.pptx | B7: PowerPoint | C7: Session or supporting resource | D7: 2016-2017 Academic Year/10/4/16 Rational Tangles/Rational Tangles 10-4.pptx | E7: MTC-090 | F7: OFR-002 | G7: Metadata inventoried | H7: https://docs.google.com/presentation/d/0B4cCTfJeL7_daGlzTnJxTmJYNFE/edit?usp=drivesdk&ouid=109901495158487957834&resourcekey=0-PvNrNHCkTPRSyRcoVjP3rQ&rtpof=true&sd=true | I7: 0B4cCTfJeL7_daGlzTnJxTmJYNFE
A8: MadVet2.pptx | B8: PowerPoint | C8: Session or supporting resource | D8: 2016-2017 Academic Year/11/1/16 Mad Vet/MadVet2.pptx | E8: MTC-116 | F8: OFR-003 | G8: Metadata inventoried | H8: https://docs.google.com/presentation/d/0B4cCTfJeL7_dek16Y01ITGZZVWM/edit?usp=drivesdk&ouid=109901495158487957834&resourcekey=0-mgZwkory8HS2tN5UyBs3kg&rtpof=true&sd=true | I8: 0B4cCTfJeL7_dek16Y01ITGZZVWM
A9: MadVetProblems.pdf | B9: PDF | C9: Session or supporting resource | D9: 2016-2017 Academic Year/11/1/16 Mad Vet/MadVetProblems.pdf | E9: MTC-116 | F9: OFR-003 | G9: Metadata inventoried | H9: https://drive.google.com/file/d/0B4cCTfJeL7_dbGxYdlBhRWlITUU/view?usp=drivesdk&resourcekey=0-PLiXbNK72XjipdpkxxMFUw | I9: 0B4cCTfJeL7_dbGxYdlBhRWlITUU
A10: MTC Meeting 3 Flyer v2.pdf | B10: PDF | C10: Agenda / announcement / institute support | D10: 2016-2017 Academic Year/11/1/16 Mad Vet/MTC Meeting 3 Flyer v2.pdf | E10: MTC-116 | F10: OFR-003 | G10: Text reviewed | H10: https://drive.google.com/file/d/0B4cCTfJeL7_dcUF3dHJHWjJiMEE/view?usp=drivesdk&resourcekey=0-81akf2SWjep3EUPUzYf7mg | I10: 0B4cCTfJeL7_dcUF3dHJHWjJiMEE
A11: MTC Meeting 4 Flyer.pdf | B11: PDF | C11: Agenda / announcement / institute support | D11: 2016-2017 Academic Year/12/6/16 Game Theory/MTC Meeting 4 Flyer.pdf | E11: MTC-087 | F11: OFR-004 | G11: Text reviewed | H11: https://drive.google.com/file/d/0B4cCTfJeL7_dZ0d4eFRvY0M2WFU/view?usp=drivesdk&resourcekey=0-BU-CIxJ-KiHzrpFxXsS3uA | I11: 0B4cCTfJeL7_dZ0d4eFRvY0M2WFU
A12: Pirates-MTC-handout.docx | B12: Word | C12: Session or supporting resource | D12: 2016-2017 Academic Year/12/6/16 Game Theory/Pirates-MTC-handout.docx | E12: MTC-087 | F12: OFR-004 | G12: Metadata inventoried | H12: https://docs.google.com/document/d/0B4cCTfJeL7_dQnVVbTNaUXc1akk/edit?usp=drivesdk&ouid=109901495158487957834&resourcekey=0-Dw79X39kyi_xt6y8z3t1Mw&rtpof=true&sd=true | I12: 0B4cCTfJeL7_dQnVVbTNaUXc1akk
A13: Pirates, Prisoners, and Chicken.pdf | B13: PDF | C13: Session or supporting resource | D13: 2016-2017 Academic Year/12/6/16 Game Theory/Pirates, Prisoners, and Chicken.pdf | E13: MTC-087 | F13: OFR-004 | G13: Metadata inventoried | H13: https://drive.google.com/file/d/0B4cCTfJeL7_dcVVOZmwxX3RVdk0/view?usp=drivesdk&resourcekey=0-OMR_byjoY0v3RnYI1RRwcg | I13: 0B4cCTfJeL7_dcVVOZmwxX3RVdk0
A14: MTC Meeting 5 Flyer.pdf | B14: PDF | C14: Agenda / announcement / institute support | D14: 2016-2017 Academic Year/2/7/17 Set/MTC Meeting 5 Flyer.pdf | E14: MTC-096 | F14: OFR-005 | G14: Text reviewed | H14: https://drive.google.com/file/d/0B4cCTfJeL7_dQ2lLeDdMUDhwX28/view?usp=drivesdk&resourcekey=0-WVYtZLMYQXEHOqfrY_cTog | I14: 0B4cCTfJeL7_dQ2lLeDdMUDhwX28
A15: MTC SET.pdf | B15: PDF | C15: Session or supporting resource | D15: 2016-2017 Academic Year/2/7/17 Set/MTC SET.pdf | E15: MTC-096 | F15: OFR-005 | G15: Metadata inventoried | H15: https://drive.google.com/file/d/0B4cCTfJeL7_ddWtmMTdJdzg1c3M/view?usp=drivesdk&resourcekey=0-MODq2DeRNzOdnB4Q9bH_VQ | I15: 0B4cCTfJeL7_ddWtmMTdJdzg1c3M
... A31: Pancakes.pdf | B31: PDF | C31: Session or supporting resource | D31: 2016-2017 Academic Year/9/6/16 Pancake Sorting/Pancakes.pdf | E31: MTC-084 | F31: OFR-001 | G31: Metadata inventoried | H31: https://drive.google.com/file/d/0B4cCTfJeL7_dUzJ0UUF1SEJ2Y3c/view?usp=drivesdk&resourcekey=0-afpiECHbahHqSGhOkT6Dsg | I31: 0B4cCTfJeL7_dUzJ0UUF1SEJ2Y3c
A32: How Playing With Math Helps Teachers Better Empathize With Students _ MindShift _ KQED News.pdf | B32: PDF | C32: Session or supporting resource | D32: 2017 Summer Institute/Articles/How Playing With Math Helps Teachers Better Empathize With Students _ MindShift _ KQED News.pdf | G32: Metadata inventoried | H32: https://drive.google.com/file/d/0B4cCTfJeL7_dM0dNNTV5SUNSa0E/view?usp=drivesdk&resourcekey=0-qVJ9teLcNqd4G-DAPyGfGQ | I32: 0B4cCTfJeL7_dM0dNNTV5SUNSa0E
A33: MateasMTMS2016.pdf | B33: PDF | C33: Session or supporting resource | D33: 2017 Summer Institute/Articles/MateasMTMS2016.pdf | G33: Metadata inventoried | H33: https://drive.google.com/file/d/0BxzKPtfFAqkTcjBfZTFLU2ZVUzQ/view?usp=drivesdk&resourcekey=0-D8MmbxmYU4C5QaHzYYVXFA | I33: 0BxzKPtfFAqkTcjBfZTFLU2ZVUzQ
A34: MateasReadingGuide.docx | B34: Word | C34: Session or supporting resource | D34: 2017 Summer Institute/Articles/MateasReadingGuide.docx | G34: Metadata inventoried | H34: https://docs.google.com/document/d/0BxzKPtfFAqkTSGdZcWVuSFlvRDQ/edit?usp=drivesdk&ouid=109901495158487957834&resourcekey=0-A4zIBTvc5Ft40o1CQ2UeCA&rtpof=true&sd=true | I34: 0BxzKPtfFAqkTSGdZcWVuSFlvRDQ
A35: Pennant-ProblemSolvingTeachingNRICH.pdf | B35: PDF | C35: Session or supporting resource | D35: 2017 Summer Institute/Articles/Pennant-ProblemSolvingTeachingNRICH.pdf | G35: Metadata inventoried | H35: https://drive.google.com/file/d/0BxzKPtfFAqkTdmRMTUhIRFM2MWM/view?usp=drivesdk&resourcekey=0-ajxqv7B9Zha4jMsXMhW_wQ | I35: 0BxzKPtfFAqkTdmRMTUhIRFM2MWM
A36: Circle-Square | B36: Google Slides | C36: Session or supporting resource | D36: 2017 Summer Institute/Circle-Square | G36: Metadata inventoried | H36: https://docs.google.com/presentation/d/1PC8elmfASTVP3gvYVM2Yi7Tmpb9RifivsmP6JtTNX9U/edit?usp=drivesdk | I36: 1PC8elmfASTVP3gvYVM2Yi7Tmpb9RifivsmP6JtTNX9U
A37: CSUDH-Lesson-Template.docx | B37: Word | C37: Session or supporting resource | D37: 2017 Summer Institute/CSUDH-Lesson-Template.docx | G37: Metadata inventoried | H37: https://docs.google.com/document/d/0BxzKPtfFAqkTS3NHZzduTmFvMWM/edit?usp=drivesdk&ouid=109901495158487957834&resourcekey=0-3aW77TZlzn5QE0yS5e_f2w&rtpof=true&sd=true | I37: 0BxzKPtfFAqkTS3NHZzduTmFvMWM
A38: LessonSharingTemplate Algebra.pptx | B38: Google Slides | C38: Session or supporting resource | D38: 2017 Summer Institute/LessonSharingTemplate Algebra.pptx | G38: Metadata inventoried | H38: https://docs.google.com/presentation/d/1PuWmbuZBRx0iByro9qraotGEXtoXe9OfbBs0Zfw_eoY/edit?usp=drivesdk | I38: 1PuWmbuZBRx0iByro9qraotGEXtoXe9OfbBs0Zfw_eoY
A39: LessonSharingTemplate.pptx | B39: PowerPoint | C39: Session or supporting resource | D39: 2017 Summer Institute/LessonSharingTemplate.pptx | G39: Metadata inventoried | H39: https://docs.google.com/presentation/d/0BxzKPtfFAqkTUWNwUHNOeV9YSW8/edit?usp=drivesdk&ouid=109901495158487957834&resourcekey=0-G9UW94xH1FV7u83O01V_3g&rtpof=true&sd=true | I39: 0BxzKPtfFAqkTUWNwUHNOeV9YSW8
A40: irritating-things.pdf | B40: PDF | C40: Session or supporting resource | D40: 2017 Summer Institute/Math Mini-Session: Number Bracelets/irritating-things.pdf | G40: Metadata inventoried | H40: https://drive.google.com/file/d/0B4cCTfJeL7_dM2VFMEJha0pSMms/view?usp=drivesdk&resourcekey=0-1dXL1McgreOo5KRfk-lF9A | I40: 0B4cCTfJeL7_dM2VFMEJha0pSMms
A41: Number Bracelets final.ppt | B41: PowerPoint | C41: Session or supporting resource | D41: 2017 Summer Institute/Math Mini-Session: Number Bracelets/Number Bracelets final.ppt | G41: Text unavailable | H41: https://docs.google.com/presentation/d/0B4cCTfJeL7_ddnNuNFRmQ3JKVWs/edit?usp=drivesdk&ouid=109901495158487957834&resourcekey=0-Q9pnQJeCFP1ytdXA5NP0CA&rtpof=true&sd=true | I41: 0B4cCTfJeL7_ddnNuNFRmQ3JKVWs
A42: Number bracelets sheet.pdf | B42: PDF | C42: Session or supporting resource | D42: 2017 Summer Institute/Math Mini-Session: Number Bracelets/Number bracelets sheet.pdf | G42: Metadata inventoried | H42: https://drive.google.com/file/d/0B4cCTfJeL7_dZ1pEYTZoQWdRdUU/view?usp=drivesdk&resourcekey=0-anDVhWQRMIX9jy45xCuQOA | I42: 0B4cCTfJeL7_dZ1pEYTZoQWdRdUU
A43: Numberbracelets.pdf | B43: PDF | C43: Session or supporting resource | D43: 2017 Summer Institute/Math Mini-Session: Number Bracelets/Numberbracelets.pdf | E43: MTC-080 | F43: OFR-013 | G43: Text unavailable | H43: https://drive.google.com/file/d/0B4cCTfJeL7_dZEszNWJvRHBDQkU/view?usp=drivesdk&resourcekey=0-JEkHg4pkfRvfDuTq1EmA7g | I43: 0B4cCTfJeL7_dZEszNWJvRHBDQkU
A44: Mastermind-Blanks.docx | B44: Word | C44: Session or supporting resource | D44: 2017 Summer Institute/Math Session I: Mastermind/Mastermind-Blanks.docx | G44: Metadata inventoried | H44: https://docs.google.com/document/d/0B4cCTfJeL7_dQXFGbXduMVBMZ2c/edit?usp=drivesdk&ouid=109901495158487957834&resourcekey=0-G5jObCIs1D12QUC8M1rDuQ&rtpof=true&sd=true | I44: 0B4cCTfJeL7_dQXFGbXduMVBMZ2c
A45: Mastermind.pptx | B45: PowerPoint | C45: Session or supporting resource | D45: 2017 Summer Institute/Math Session I: Mastermind/Mastermind.pptx | E45: MTC-062 | F45: OFR-012 | G45: Text reviewed | H45: https://docs.google.com/presentation/d/0B4cCTfJeL7_dbkR1d0RQeHRMclU/edit?usp=drivesdk&ouid=109901495158487957834&resourcekey=0-qaLSVqn8XKSsNH4sKGV55g&rtpof=true&sd=true | I45: 0B4cCTfJeL7_dbkR1d0RQeHRMclU
A46: Logic Presentation.pptx | B46: PowerPoint | C46: Session or supporting resource | D46: 2017 Summer Institute/Math Session II: Knights and Knaves/Logic Presentation.pptx | E46: MTC-057 | F46: OFR-011 | G46: Text reviewed | H46: https://docs.google.com/presentation/d/0B2XvpmARE9ZbMnZCM0ZOaHZXSVk/edit?usp=drivesdk&ouid=109901495158487957834&resourcekey=0-V7nKYNXuHYTwHhbaPrZV6w&rtpof=true&sd=true | I46: 0B2XvpmARE9ZbMnZCM0ZOaHZXSVk
A47: Part 1 Knights and Knaves Updated.docx | B47: Word | C47: Session or supporting resource | D47: 2017 Summer Institute/Math Session II: Knights and Knaves/Part 1 Knights and Knaves Updated.docx | G47: Metadata inventoried | H47: https://docs.google.com/document/d/0B2XvpmARE9ZbTTItV19aQWZPd1k/edit?usp=drivesdk&ouid=109901495158487957834&resourcekey=0-ruEUP7nXAsZik6Pgpsw9Ig&rtpof=true&sd=true | I47: 0B2XvpmARE9ZbTTItV19aQWZPd1k
A48: Sprouts.pptx | B48: PowerPoint | C48: Session or supporting resource | D48: 2017 Summer Institute/Math Session III: Sprouts/Sprouts.pptx | E48: MTC-106 | F48: OFR-015 | G48: Text reviewed | H48: https://docs.google.com/presentation/d/0B4cCTfJeL7_dUGgtc2hVRVZkZFU/edit?usp=drivesdk&ouid=109901495158487957834&resourcekey=0-xyg98UR1GYtUjh9gnA0xIg&rtpof=true&sd=true | I48: 0B4cCTfJeL7_dUGgtc2hVRVZkZFU
A49: Instant Insanity.pptx | B49: PowerPoint | C49: Session or supporting resource | D49: 2017 Summer Institute/Math Session IV: Instant Insanity/Instant Insanity.pptx | E49: MTC-045 | F49: OFR-010 | G49: Text reviewed | H49: https://docs.google.com/presentation/d/0B4cCTfJeL7_dZ084MGZNUjVBU1E/edit?usp=drivesdk&ouid=109901495158487957834&resourcekey=0-xqQaukkaqbnIwZhtqkr3HQ&rtpof=true&sd=true | I49: 0B4cCTfJeL7_dZ084MGZNUjVBU1E
A50: Spaghetti Tower Challenge.pptx | B50: PowerPoint | C50: Session or supporting resource | D50: 2017 Summer Institute/Spaghetti Tower Challenge.pptx | E50: MTC-103 | F50: OFR-014 | G50: Text reviewed | H50: https://docs.google.com/presentation/d/0B4cCTfJeL7_dNkFpWHhUbkk5cmM/edit?usp=drivesdk&ouid=109901495158487957834&resourcekey=0-14wM74J9lM5YAVbPFV4nyA&rtpof=true&sd=true | I50: 0B4cCTfJeL7_dNkFpWHhUbkk5cmM
A51: Summer Institute Flyer 2017.pdf | B51: PDF | C51: Agenda / announcement / institute support | D51: 2017 Summer Institute/Summer Institute Flyer 2017.pdf | E51: MTC-045; MTC-057; MTC-062; MTC-080; MTC-103; MTC-106 | F51: OFR-010; OFR-011; OFR-012; OFR-013; OFR-014; OFR-015 | G51: Text reviewed | H51: https://drive.google.com/file/d/0B4cCTfJeL7_dU3lfY2t4ckNZQ3M/view?usp=drivesdk&resourcekey=0-mgNytrTm-j1DMeP0R_Ki6w | I51: 0B4cCTfJeL7_dU3lfY2t4ckNZQ3M
A52: 7th Grade 7NS.1 Alexandra Sluga, Odetta Moore, Richard Tejada (7th Grade) | B52: Google Doc | C52: Participant work / planning resources | D52: 2017 Summer Institute/Upload Lesson Plans Here/7th Grade 7NS.1 Alexandra Sluga, Odetta Moore, Richard Tejada (7th Grade) | G52: Metadata inventoried | H52: https://docs.google.com/document/d/1m4krlUlC_uusHyJKBIFLhBEaiayqUKHkxZ9GwjQb3-4/edit?usp=drivesdk | I52: 1m4krlUlC_uusHyJKBIFLhBEaiayqUKHkxZ9GwjQb3-4
A53: 7th Grade 7RP2A | B53: Google Slides | C53: Participant work / planning resources | D53: 2017 Summer Institute/Upload Lesson Plans Here/7th Grade 7RP2A | G53: Metadata inventoried | H53: https://docs.google.com/presentation/d/1f0rgfEbMdO6oRQP5jLvTyPII5lqajqFPd8BwDUdyE2A/edit?usp=drivesdk | I53: 1f0rgfEbMdO6oRQP5jLvTyPII5lqajqFPd8BwDUdyE2A
